<?xml version="1.0"?>
<robot name="panda" xmlns:xacro="http://www.ros.org/wiki/xacro">
  <xacro:include filename="$(find acg_resources_panda_description)/urdf/inertial.xacro"/>
  <xacro:arg name="tf_prefix" default="panda/"/>

  <link name="world"/>

  <joint name="world_to_base" type="fixed">
    <origin rpy="0 0 0" xyz="0 0 0"/>
    <parent link="world"/>
    <child link="$(arg tf_prefix)link0"/>
  </joint>

  <link name="$(arg tf_prefix)link0">
    <visual>
      <geometry>
        <mesh filename="package://acg_resources_panda_description/meshes/visual/link0.dae"/>
      </geometry>
    </visual>
    <collision>
      <geometry>
        <mesh filename="package://acg_resources_panda_description/meshes/collision/link0.stl"/>
      </geometry>
    </collision>
    <xacro:inertial_props name="link0"/>
  </link>
  <link name="$(arg tf_prefix)link1">
    <visual>
      <geometry>
        <mesh filename="package://acg_resources_panda_description/meshes/visual/link1.dae"/>
      </geometry>
    </visual>
    <collision>
      <geometry>
        <mesh filename="package://acg_resources_panda_description/meshes/collision/link1.stl"/>
      </geometry>
    </collision>
    <xacro:inertial_props name="link1"/>
  </link>
  <joint name="$(arg tf_prefix)joint1" type="revolute">
    <safety_controller k_position="100.0" k_velocity="40.0" soft_lower_limit="-2.8973" soft_upper_limit="2.8973"/>
    <origin rpy="0 0 0" xyz="0 0 0.333"/>
    <parent link="$(arg tf_prefix)link0"/>
    <child link="$(arg tf_prefix)link1"/>
    <axis xyz="0 0 1"/>
    <limit effort="87" lower="-2.9671" upper="2.9671" velocity="2.3925"/>
  </joint>
  <link name="$(arg tf_prefix)link2">
    <visual>
      <geometry>
        <mesh filename="package://acg_resources_panda_description/meshes/visual/link2.dae"/>
      </geometry>
    </visual>
    <collision>
      <geometry>
        <mesh filename="package://acg_resources_panda_description/meshes/collision/link2.stl"/>
      </geometry>
    </collision>
    <xacro:inertial_props name="link2"/>
  </link>
  <joint name="$(arg tf_prefix)joint2" type="revolute">
    <safety_controller k_position="100.0" k_velocity="40.0" soft_lower_limit="-1.7628" soft_upper_limit="1.7628"/>
    <origin rpy="-1.57079632679 0 0" xyz="0 0 0"/>
    <parent link="$(arg tf_prefix)link1"/>
    <child link="$(arg tf_prefix)link2"/>
    <axis xyz="0 0 1"/>
    <limit effort="87" lower="-1.8326" upper="1.8326" velocity="2.3925"/>
  </joint>
  <link name="$(arg tf_prefix)link3">
    <visual>
      <geometry>
        <mesh filename="package://acg_resources_panda_description/meshes/visual/link3.dae"/>
      </geometry>
    </visual>
    <collision>
      <geometry>
        <mesh filename="package://acg_resources_panda_description/meshes/collision/link3.stl"/>
      </geometry>
    </collision>
    <xacro:inertial_props name="link3"/>
  </link>
  <joint name="$(arg tf_prefix)joint3" type="revolute">
    <safety_controller k_position="100.0" k_velocity="40.0" soft_lower_limit="-2.8973" soft_upper_limit="2.8973"/>
    <origin rpy="1.57079632679 0 0" xyz="0 -0.316 0"/>
    <parent link="$(arg tf_prefix)link2"/>
    <child link="$(arg tf_prefix)link3"/>
    <axis xyz="0 0 1"/>
    <limit effort="87" lower="-2.9671" upper="2.9671" velocity="2.3925"/>
  </joint>
  <link name="$(arg tf_prefix)link4">
    <visual>
      <geometry>
        <mesh filename="package://acg_resources_panda_description/meshes/visual/link4.dae"/>
      </geometry>
    </visual>
    <collision>
      <geometry>
        <mesh filename="package://acg_resources_panda_description/meshes/collision/link4.stl"/>
      </geometry>
    </collision>
    <xacro:inertial_props name="link4"/>
  </link>
  <joint name="$(arg tf_prefix)joint4" type="revolute">
    <safety_controller k_position="100.0" k_velocity="40.0" soft_lower_limit="-3.0718" soft_upper_limit="0.0175"/>
    <origin rpy="1.57079632679 0 0" xyz="0.0825 0 0"/>
    <parent link="$(arg tf_prefix)link3"/>
    <child link="$(arg tf_prefix)link4"/>
    <axis xyz="0 0 1"/>
    <limit effort="87" lower="-3.1416" upper="0.0873" velocity="2.3925"/>
  </joint>
  <link name="$(arg tf_prefix)link5">
    <visual>
      <geometry>
        <mesh filename="package://acg_resources_panda_description/meshes/visual/link5.dae"/>
      </geometry>
    </visual>
    <collision>
      <geometry>
        <mesh filename="package://acg_resources_panda_description/meshes/collision/link5.stl"/>
      </geometry>
    </collision>
    <xacro:inertial_props name="link5"/>
  </link>
  <joint name="$(arg tf_prefix)joint5" type="revolute">
    <safety_controller k_position="100.0" k_velocity="40.0" soft_lower_limit="-2.8973" soft_upper_limit="2.8973"/>
    <origin rpy="-1.57079632679 0 0" xyz="-0.0825 0.384 0"/>
    <parent link="$(arg tf_prefix)link4"/>
    <child link="$(arg tf_prefix)link5"/>
    <axis xyz="0 0 1"/>
    <limit effort="12" lower="-2.9671" upper="2.9671" velocity="2.8710"/>
  </joint>
  <link name="$(arg tf_prefix)link6">
    <visual>
      <geometry>
        <mesh filename="package://acg_resources_panda_description/meshes/visual/link6.dae"/>
      </geometry>
    </visual>
    <collision>
      <geometry>
        <mesh filename="package://acg_resources_panda_description/meshes/collision/link6.stl"/>
      </geometry>
    </collision>
    <xacro:inertial_props name="link6"/>
  </link>
  <joint name="$(arg tf_prefix)joint6" type="revolute">
    <safety_controller k_position="100.0" k_velocity="40.0" soft_lower_limit="-0.0175" soft_upper_limit="3.7525"/>
    <origin rpy="1.57079632679 0 0" xyz="0 0 0"/>
    <parent link="$(arg tf_prefix)link5"/>
    <child link="$(arg tf_prefix)link6"/>
    <axis xyz="0 0 1"/>
    <limit effort="12" lower="-0.0873" upper="3.8223" velocity="2.8710"/>
  </joint>
  <link name="$(arg tf_prefix)link7">
    <visual>
      <geometry>
        <mesh filename="package://acg_resources_panda_description/meshes/visual/link7.dae"/>
      </geometry>
    </visual>
    <collision>
      <geometry>
        <mesh filename="package://acg_resources_panda_description/meshes/collision/link7.stl"/>
      </geometry>
    </collision>
    <xacro:inertial_props name="link7"/>
  </link>
  <joint name="$(arg tf_prefix)joint7" type="revolute">
    <safety_controller k_position="100.0" k_velocity="40.0" soft_lower_limit="-2.8973" soft_upper_limit="2.8973"/>
    <origin rpy="1.57079632679 0 0" xyz="0.088 0 0"/>
    <parent link="$(arg tf_prefix)link6"/>
    <child link="$(arg tf_prefix)link7"/>
    <axis xyz="0 0 1"/>
    <limit effort="12" lower="-2.9671" upper="2.9671" velocity="2.8710"/>
  </joint>
  <link name="$(arg tf_prefix)link8"/>
  <joint name="$(arg tf_prefix)joint8" type="fixed">
    <origin rpy="0 0 0" xyz="0 0 0.107"/>
    <parent link="$(arg tf_prefix)link7"/>
    <child link="$(arg tf_prefix)link8"/>
    <axis xyz="0 0 0"/>
  </joint>
  <joint name="$(arg tf_prefix)hand_joint" type="fixed">
    <parent link="$(arg tf_prefix)link8"/>
    <child link="$(arg tf_prefix)hand"/>
    <origin rpy="0 0 -0.785398163397" xyz="0 0 0"/>
  </joint>
  <link name="$(arg tf_prefix)hand">
    <visual>
      <geometry>
        <mesh filename="package://acg_resources_panda_description/meshes/visual/hand.dae"/>
      </geometry>
    </visual>
    <collision>
      <geometry>
        <mesh filename="package://acg_resources_panda_description/meshes/collision/hand.stl"/>
      </geometry>
    </collision>
    <xacro:inertial_props name="hand"/>
  </link>
  <link name="$(arg tf_prefix)leftfinger">
    <visual>
      <geometry>
        <mesh filename="package://acg_resources_panda_description/meshes/visual/finger.dae"/>
      </geometry>
    </visual>
    <collision>
      <geometry>
        <mesh filename="package://acg_resources_panda_description/meshes/collision/finger.stl"/>
      </geometry>
    </collision>
    <xacro:inertial_props name="leftfinger"/>
  </link>
  <link name="$(arg tf_prefix)rightfinger">
    <visual>
      <origin rpy="0 0 3.14159265359" xyz="0 0 0"/>
      <geometry>
        <mesh filename="package://acg_resources_panda_description/meshes/visual/finger.dae"/>
      </geometry>
    </visual>
    <collision>
      <origin rpy="0 0 3.14159265359" xyz="0 0 0"/>
      <geometry>
        <mesh filename="package://acg_resources_panda_description/meshes/collision/finger.stl"/>
      </geometry>
    </collision>
    <xacro:inertial_props name="rightfinger"/>
  </link>
  <joint name="$(arg tf_prefix)finger_joint1" type="prismatic">
    <parent link="$(arg tf_prefix)hand"/>
    <child link="$(arg tf_prefix)leftfinger"/>
    <origin rpy="0 0 0" xyz="0 0 0.0584"/>
    <axis xyz="0 1 0"/>
    <limit effort="20" lower="0.0" upper="0.04" velocity="0.2"/>
  </joint>
  <joint name="$(arg tf_prefix)finger_joint2" type="prismatic">
    <parent link="$(arg tf_prefix)hand"/>
    <child link="$(arg tf_prefix)rightfinger"/>
    <origin rpy="0 0 0" xyz="0 0 0.0584"/>
    <axis xyz="0 -1 0"/>
    <limit effort="20" lower="0.0" upper="0.04" velocity="0.2"/>
    <mimic joint="$(arg tf_prefix)finger_joint1"/>
  </joint>
</robot>
