<?xml version="1.0"?>
<robot name="fanuc_m20ia_35m" xmlns:xacro="http://www.ros.org/wiki/xacro">
  <xacro:arg name="tf_prefix" default="fanuc_m20ia_35m/"/>
  <link name="$(arg tf_prefix)link0">
    <visual>
      <origin rpy="0 0 0" xyz="0 0 0"/>
      <geometry>
        <mesh filename="package://acg_resources_fanuc_m20ia_35m_description/meshes/visual/link0.dae"/>
      </geometry>
    </visual>
    <collision>
      <origin rpy="0 0 0" xyz="0 0 0"/>
      <geometry>
        <mesh filename="package://acg_resources_fanuc_m20ia_35m_description/meshes/collision/link0.stl"/>
      </geometry>
    </collision>
  </link>
  <link name="$(arg tf_prefix)link1">
    <visual>
      <origin rpy="0 0 0" xyz="0 0 -0.525"/>
      <geometry>
        <mesh filename="package://acg_resources_fanuc_m20ia_35m_description/meshes/visual/link1.dae"/>
      </geometry>
    </visual>
    <collision>
      <origin rpy="0 0 0" xyz="0 0 -0.525"/>
      <geometry>
        <mesh filename="package://acg_resources_fanuc_m20ia_35m_description/meshes/collision/link1.stl"/>
      </geometry>
    </collision>
  </link>
  <joint name="$(arg tf_prefix)joint1" type="revolute">
    <origin rpy="0 0 0" xyz="0 0 0.525"/>
    <parent link="$(arg tf_prefix)link0"/>
    <child link="$(arg tf_prefix)link1"/>
    <axis xyz="0 0 1"/>
    <limit effort="2500" lower="-3.228859" upper="3.228859" velocity="3.14"/>
  </joint>
  <link name="$(arg tf_prefix)link2">
    <visual>
      <origin rpy="${pi/2} 0 ${pi/2}" xyz="-0.525 -0.15 0"/>
      <geometry>
        <mesh filename="package://acg_resources_fanuc_m20ia_35m_description/meshes/visual/link2.dae"/>
      </geometry>
    </visual>
    <collision>
      <origin rpy="${pi/2} 0 ${pi/2}" xyz="-0.525 -0.15 0"/>
      <geometry>
        <mesh filename="package://acg_resources_fanuc_m20ia_35m_description/meshes/collision/link2.stl"/>
      </geometry>
    </collision>
  </link>
  <joint name="$(arg tf_prefix)joint2" type="revolute">
    <origin rpy="${-pi/2} ${-pi/2} 0" xyz="0.150 0 0"/>
    <parent link="$(arg tf_prefix)link1"/>
    <child link="$(arg tf_prefix)link2"/>
    <axis xyz="0 0 1"/>
    <limit effort="2500" lower="-1.745329" upper="2.792527" velocity="3.14"/>
  </joint>
  <link name="$(arg tf_prefix)link3">
    <visual>
      <origin rpy="${pi/2} 0 ${pi/2}" xyz="-1.315 -0.15 0"/>
      <geometry>
        <mesh filename="package://acg_resources_fanuc_m20ia_35m_description/meshes/visual/link3.dae"/>
      </geometry>
    </visual>
    <collision>
      <origin rpy="${pi/2} 0 ${pi/2}" xyz="-1.315 -0.15 0"/>
      <geometry>
        <mesh filename="package://acg_resources_fanuc_m20ia_35m_description/meshes/collision/link3.stl"/>
      </geometry>
    </collision>
  </link>
  <joint name="$(arg tf_prefix)joint3" type="revolute">
    <origin rpy="0 0 0" xyz="0.79 0 0"/>
    <parent link="$(arg tf_prefix)link2"/>
    <child link="$(arg tf_prefix)link3"/>
    <axis xyz="0 0 1"/>
    <limit effort="2000" lower="-3.228859" upper="4.766494" velocity="3.49"/>
  </joint>
  <link name="$(arg tf_prefix)link4">
    <visual>
      <origin rpy="${-pi} ${-pi/2} 0" xyz="-1.465 0 -1.01"/>
      <geometry>
        <mesh filename="package://acg_resources_fanuc_m20ia_35m_description/meshes/visual/link4.dae"/>
      </geometry>
    </visual>
    <collision>
      <origin rpy="${-pi} ${-pi/2} 0" xyz="-1.465 0 -1.01"/>
      <geometry>
        <mesh filename="package://acg_resources_fanuc_m20ia_35m_description/meshes/collision/link4.stl"/>
      </geometry>
    </collision>
  </link>
  <joint name="$(arg tf_prefix)joint4" type="revolute">
    <origin rpy="-1.5708 0 0" xyz="0.15 0.86 0"/>
    <parent link="$(arg tf_prefix)link3"/>
    <child link="$(arg tf_prefix)link4"/>
    <axis xyz="0 0 1"/>
    <limit effort="110" lower="-3.490659" upper="3.490659" velocity="6.11"/>
  </joint>
  <link name="$(arg tf_prefix)link5">
    <visual>
      <origin rpy="${pi/2} 0 ${pi/2}" xyz="-1.465 -1.01 0"/>
      <geometry>
        <mesh filename="package://acg_resources_fanuc_m20ia_35m_description/meshes/visual/link5.dae"/>
      </geometry>
    </visual>
    <collision>
      <origin rpy="${pi/2} 0 ${pi/2}" xyz="-1.465 -1.01 0"/>
      <geometry>
        <mesh filename="package://acg_resources_fanuc_m20ia_35m_description/meshes/collision/link5.stl"/>
      </geometry>
    </collision>
  </link>
  <joint name="$(arg tf_prefix)joint5" type="revolute">
    <origin rpy="${pi/2} 0 0" xyz=" 0 0 0"/>
    <parent link="$(arg tf_prefix)link4"/>
    <child link="$(arg tf_prefix)link5"/>
    <axis xyz="0 0 1"/>
    <limit effort="110" lower="-2.443461" upper="2.443461" velocity="6.11"/>
  </joint>
  <link name="$(arg tf_prefix)link6">
    <visual>
      <origin rpy="0 0 0" xyz="0 0 0"/>
      <geometry>
        <mesh filename="package://acg_resources_fanuc_m20ia_35m_description/meshes/visual/link6.dae"/>
      </geometry>
    </visual>
    <collision>
      <origin rpy="0 0 0" xyz="0 0 0"/>
      <geometry>
        <mesh filename="package://acg_resources_fanuc_m20ia_35m_description/meshes/collision/link6.stl"/>
      </geometry>
    </collision>
  </link>
  <joint name="$(arg tf_prefix)joint6" type="revolute">
    <origin rpy="${-pi/2} 0 0" xyz="0 0.1 0"/>
    <parent link="$(arg tf_prefix)link5"/>
    <child link="$(arg tf_prefix)link6"/>
    <axis xyz="0 0 1"/>
    <limit effort="60" lower="-7.853982" upper="7.853982" velocity="6.98"/>
  </joint>
</robot>
